<?xml version="1.0" encoding="UTF-8"?><rss version="2.0"
	xmlns:content="http://purl.org/rss/1.0/modules/content/"
	xmlns:wfw="http://wellformedweb.org/CommentAPI/"
	xmlns:dc="http://purl.org/dc/elements/1.1/"
	xmlns:atom="http://www.w3.org/2005/Atom"
	xmlns:sy="http://purl.org/rss/1.0/modules/syndication/"
	xmlns:slash="http://purl.org/rss/1.0/modules/slash/"
	>

<channel>
	<title>异常 &#8211; 有组织在!</title>
	<atom:link href="https://uzzz.org/tag/yichang/feed" rel="self" type="application/rss+xml" />
	<link>https://uzzz.org/</link>
	<description></description>
	<lastBuildDate>Sun, 05 Mar 2017 08:21:10 +0000</lastBuildDate>
	<language>zh-CN</language>
	<sy:updatePeriod>
	hourly	</sy:updatePeriod>
	<sy:updateFrequency>
	1	</sy:updateFrequency>
	<generator>https://wordpress.org/?v=5.2.4</generator>

<image>
	<url>https://uzzz.org/wp-content/uploads/2019/10/cropped-icon-32x32.png</url>
	<title>异常 &#8211; 有组织在!</title>
	<link>https://uzzz.org/</link>
	<width>32</width>
	<height>32</height>
</image> 
	<item>
		<title>java中try 与catch的使用</title>
		<link>https://uzzz.org/article/1538.html</link>
				<pubDate>Sun, 05 Mar 2017 08:21:10 +0000</pubDate>
		<dc:creator><![CDATA[fandyvon]]></dc:creator>
				<category><![CDATA[java]]></category>
		<category><![CDATA[exception]]></category>
		<category><![CDATA[异常]]></category>

		<guid isPermaLink="false">http://wp.uzzz.org/article/1538.html</guid>
				<description><![CDATA[try{ //代码区 }catch(Exception e){ //异常处理 } 代码区如果有错误，就会返回所写异常的处理。 &#160; 首先要清楚，如果没有try的话，出现异常会导致程序崩溃。 而try则可以保证程序的正常运行下去，比如说： try{ int i = 1/0; }catch(Exception e){ &#8230;&#8230;.. }]]></description>
								<content:encoded><![CDATA[<div id="article_content" class="article_content clearfix">
 <link rel="stylesheet" href="https://csdnimg.cn/release/phoenix/template/css/ck_htmledit_views-3019150162.css">
 <link rel="stylesheet" href="https://csdnimg.cn/release/phoenix/template/css/ck_htmledit_views-3019150162.css">
<div class="htmledit_views" id="content_views">
   try{<br />
  <br /> //代码区<br />
  <br /> }catch(Exception e){<br />
  <br /> //异常处理<br />
  <br /> }<br />
  <br /> 代码区如果有错误，就会返回所写异常的处理。<br />
  <br /> &nbsp;<br />
  <br /> 首先要清楚，如果没有try的话，出现异常会导致程序崩溃。<br />
  <br /> 而try则可以保证程序的正常运行下去，比如说：<br />
  <br /> try{<br />
  <br /> int i = 1/0;<br />
  <br /> }catch(Exception e){<br />
  <br /> &#8230;&#8230;..<br />
  <br /> }<br />
  <br /> 一个计算的话，如果除数为0，则会报错，如果没有try的话，程序直接崩溃。用try的话，则可以让程序运行下去，并且输出为什么出错！<br />
  <br /> try catch 是捕捉try部分的异常，当你没有try catch的时候，如果出现异常则程序报错，加上try catch，出现异常程序正常运行，只是把错误信息存储到Exception里，所以catch是用来提取异常信息的，你可以在Catch部分加上一句System.out.println(e.ToString());，如果出现异常可以把异常打印出来<br />
  <br /> &nbsp;<br />
  </p>
<p>Java的异常处理机制(try…catch…finally)</p>
<p>1 引子<br /> try…catch…finally恐怕是大家再熟悉不过的语句了，而且感觉用起来也是很简单，逻辑上似乎也是很容易理解。不过，我亲自体验的“教训”告诉我，这个东西可不是想象中的那么简单、听话。不信？那你看看下面的代码，“猜猜”它执行后的结果会是什么？不要往后看答案、也不许执行代码看真正答案哦。如果你的答案是正确，那么这篇文章你就不用浪费时间看啦。</p>
<pre><code class="language-java">public class TestException {
	public TestException() {
	}

	boolean testEx() throws Exception {
		boolean ret = true;
		try {
			ret = testEx1();
		} catch (Exception e) {
			System.out.println("testEx, catch exception");
			ret = false;
			throw e;
		} finally {
			System.out.println("testEx, finally; return value=" + ret);
			return ret;
		}
	}

	boolean testEx1() throws Exception {
		boolean ret = true;
		try {
			ret = testEx2();
			if (!ret) {
				return false;
			}
			System.out.println("testEx1, at the end of try");
			return ret;
		} catch (Exception e) {
			System.out.println("testEx1, catch exception");
			ret = false;
			throw e;
		} finally {
			System.out.println("testEx1, finally; return value=" + ret);
			return ret;
		}
	}

	boolean testEx2() throws Exception {
		boolean ret = true;
		try {
			int b = 12;
			int c;
			for (int i = 2; i &gt;= -2; i--) {
				c = b / i;
				System.out.println("i=" + i);
			}
			return true;
		} catch (Exception e) {
			System.out.println("testEx2, catch exception");
			ret = false;
			throw e;
		} finally {
			System.out.println("testEx2, finally; return value=" + ret);	
			return ret;   //有返回值，程序正常结束
		}
		
	}

	public static void main(String[] args) {
		TestException testException1 = new TestException();
		try {
			testException1.testEx();
		} catch (Exception e) {
			e.printStackTrace();
		}
	}
}</code></pre>
<p>你的答案是什么？是下面的答案吗？<br />
  <br /> i=2<br />
  <br /> i=1<br />
  <br /> testEx2, catch exception<br />
  <br /> testEx2, finally; return value=false<br />
  <br /> testEx1, catch exception<br />
  <br /> testEx1, finally; return value=false<br />
  <br /> testEx, catch exception<br />
  <br /> testEx, finally; return value=false<br />
  <br /> 如果你的答案真的如上面所说，那么你错啦。^_^，那就建议你仔细看一看这篇文章或者拿上面的代码按各种不同的情况修改、执行、测试，你会发现有很多事情不是原来想象中的那么简单的。<br />
  <br /> 现在公布正确答案：<br />
  <br /> i=2<br />
  <br /> i=1<br />
  <br /> testEx2, catch exception<br />
  <br /> testEx2, finally; return value=false<br />
  <br /> testEx1, finally; return value=false<br />
  <br /> testEx, finally; return value=false</p>
<p> 2 基础知识 </p>
<p>2.1 相关概念<br /> 例外是在程序运行过程中发生的异常事件，比如除0溢出、数组越界、文件找不到等，这些事件的发生将阻止程序的正常运行。为了加强程序的鲁棒性，程序设计时，必须考虑到可能发生的异常事件并做出相应的处理。C语言中，通过使用if语句来判断是否出现了例外，同时，调用函数通过被调用函数的返回值感知在被调用函数中产生的例外事件并进行处理。全程变量ErroNo常常用来反映一个异常事件的类型。但是，这种错误处理机制会导致不少问题。<br /> Java通过面向对象的方法来处理例外。在一个方法的运行过程中，如果发生了例外，则这个方法生成代表该例外的一个对象，并把它交给运行时系统，运行时系统寻找相应的代码来处理这一例外。我们把生成例外对象并把它提交给运行时系统的过程称为抛弃(throw)一个例外。运行时系统在方法的调用栈中查找，从生成例外的方法开始进行回朔，直到找到包含相应例外处理的方法为止，这一个过程称为捕获(catch)一个例外。</p>
<p>2.2 Throwable类及其子类<br /> 用面向对象的方法处理例外，就必须建立类的层次。类 Throwable位于这一类层次的最顶层，只有它的后代才可以做为一个例外被抛弃。图1表示了例外处理的类层次。<br /> 从图中可以看出，类Throwable有两个直接子类：Error和Exception。Error类对象（如动态连接错误等），由Java虚拟机生成并抛弃（通常，Java程序不对这类例外进行处理）；Exception类对象是Java程序处理或抛弃的对象。它有各种不同的子类分别对应于不同类型的例外。其中类RuntimeException代表运行时由Java虚拟机生成的例外，如算术运算例外ArithmeticException(由除0错等导致)、数组越界例外ArrayIndexOutOfBoundsException等；其它则为非运行时例外，如输入输出例外IOException等。Java编译器要求Java程序必须捕获或声明所有的非运行时例外，但对运行时例外可以不做处理。<br /><img src="https://uzshare.com/_p?https://img-blog.csdn.net/20170305171344279" alt=""></p>
<p>2.3 异常处理关键字<br /> Java的异常处理是通过5个关键字来实现的：try，catch，throw，throws，finally。<br /> Throws: &nbsp;Lists the exceptions a method could throw.<br /> Throw: &nbsp; Transfers control of the method to the exception handler.<br /> Try： &nbsp; &nbsp;Opening exception-handling statement.<br /> Catch： &nbsp;Captures the exception.<br /> Finally： Runs its code before terminating the program.</p>
<p> 2.3.1 try语句　<br /> try语句用大括号{}指定了一段代码，该段代码可能会抛弃一个或多个例外。</p>
<p> 2.3.2 catch语句　<br /> catch语句的参数类似于方法的声明，包括一个例外类型和一个例外对象。例外类型必须为Throwable类的子类，它指明了catch语句所处理的例外类型，例外对象则由运行时系统在try所指定的代码块中生成并被捕获，大括号中包含对象的处理，其中可以调用对象的方法。<br /> catch语句可以有多个，分别处理不同类的例外。Java运行时系统从上到下分别对每个catch语句处理的例外类型进行检测，直到找到类型相匹配的catch语句为止。这里，类型匹配指catch所处理的例外类型与生成的例外对象的类型完全一致或者是它的父类，因此，catch语句的排列顺序应该是从特殊到一般。<br /> 也可以用一个catch语句处理多个例外类型，这时它的例外类型参数应该是这多个例外类型的父类，程序设计中要根据具体的情况来选择catch语句的例外处理类型。　</p>
<p> 2.3.3 finally语句　<br /> try所限定的代码中，当抛弃一个例外时，其后的代码不会被执行。通过finally语句可以指定一块代码。无论try所指定的程序块中抛弃或不抛弃例外，也无论catch语句的例外类型是否与所抛弃的例外的类型一致，finally所指定的代码都要被执行，它提供了统一的出口。通常在finally语句中可以进行资源的清除工作。如关闭打开的文件等。</p>
<p> 2.3.4 throws语句　<br /> throws总是出现在一个函数头中，用来标明该成员函数可能抛出的各种异常。对大多数Exception子类来说，Java 编译器会强迫你声明在一个成员函数中抛出的异常的类型。如果异常的类型是Error或 RuntimeException， 或它们的子类，这个规则不起作用， 因为这在程序的正常部分中是不期待出现的。 如果你想明确地抛出一个RuntimeException，你必须用throws语句来声明它的类型。</p>
<p> 2.3.5 throw语句　<br /> throw总是出现在函数体中，用来抛出一个异常。程序会在throw语句后立即终止，它后面的语句执行不到，然后在包含它的所有try块中（可能在上层调用函数中）从里向外寻找含有与其匹配的catch子句的try块。</p>
<p> 3 关键字及其中语句流程详解<br /> 3.1 try的嵌套<br /> 你可以在一个成员函数调用的外面写一个try语句，在这个成员函数内部，写另一个try语句保护其他代码。每当遇到一个try语句，异常的框架就放到堆栈上面，直到所有的try语句都完成。如果下一级的try语句没有对某种异常进行处理，堆栈就会展开，直到遇到有处理这种异常的try语句。下面是一个try语句嵌套的例子。</p>
<pre><code class="language-java">class MultiNest {
    static void procedure() {
        try {
            int a = 0;
            int b = 42/a;
        } catch(java.lang.ArithmeticException e) {
            System.out.println("in procedure, catch ArithmeticException: " + e);
        }
    }
    public static void main(String args[]) {
        try {
            procedure();
        } catch(java.lang. Exception e) {
            System.out.println("in main, catch Exception: " + e);
        }
    }
}</code></pre>
<p>这个例子执行的结果为：</p>
<p> in procedure, catch ArithmeticException: java.lang.ArithmeticException: / by zero<br />
  <br /> 成员函数procedure里有自己的try/catch控制，所以main不用去处理 ArrayIndexOutOfBoundsException；当然如果如同最开始我们做测试的例子一样，在procedure中catch到异常时使用throw e;语句将异常抛出，那么main当然还是能够捕捉并处理这个procedure抛出来的异常。例如在procedure函数的catch中的System.out语句后面增加throw e;语句之后，执行结果就变为：<br />
  <br /> in procedure, catch ArithmeticException: java.lang.ArithmeticException: / by zero<br />
  <br /> in main, catch Exception: java.lang.ArithmeticException: / by zero</p>
<p> 3.2 try-catch程序块的执行流程以及执行结果<br />
  <br /> 相对于try-catch-finally程序块而言，try-catch的执行流程以及执行结果还是比较简单的。<br />
  <br /> 首先执行的是try语句块中的语句，这时可能会有以下三种情况：<br />
  <br /> &nbsp; &nbsp; 1．如果try块中所有语句正常执行完毕，那么就不会有其他的“动作”被执行，整个try-catch程序块正常完成。<br />
  <br /> &nbsp; &nbsp; 2．如果try语句块在执行过程中碰到异常V，这时又分为两种情况进行处理：<br />
  <br /> &#8211;&gt;如果异常V能够被与try相应的catch块catch到，那么第一个catch到这个异常的catch块（也是离try最近的一个与异常V匹配的catch块）将被执行；如果catch块执行正常，那么try-catch程序块的结果就是“正常完成”；如果该catch块由于原因R突然中止，那么try-catch程序块的结果就是“由于原因R突然中止（completes abruptly）”。<br />
  <br /> &#8211;&gt;如果异常V没有catch块与之匹配，那么这个try-catch程序块的结果就是“由于抛出异常V而突然中止（completes abruptly）”。<br />
  <br /> &nbsp; &nbsp; 3．如果try由于其他原因R突然中止（completes abruptly），那么这个try-catch程序块的结果就是“由于原因R突然中止（completes abruptly）“。<br />
  <br /> &nbsp; &nbsp;&nbsp;<br />
  <br /> 3.3 try-catch-finally程序块的执行流程以及执行结果<br />
  <br /> try-catch-finally程序块的执行流程以及执行结果比较复杂。<br />
  <br /> 首先执行的是try语句块中的语句，这时可能会有以下三种情况：<br />
  <br /> 1．如果try块中所有语句正常执行完毕，那么finally块的就会被执行，这时分为以下两种情况：<br />
  <br /> &#8211;&gt;如果finally块执行顺利，那么整个try-catch-finally程序块正常完成。<br />
  <br /> &#8211;&gt;如果finally块由于原因R突然中止，那么try-catch-finally程序块的结局是“由于原因R突然中止（completes abruptly）”<br />
  <br /> 2．如果try语句块在执行过程中碰到异常V，这时又分为两种情况进行处理：<br />
  <br /> &#8211;&gt;如果异常V能够被与try相应的catch块catch到，那么第一个catch到这个异常的catch块（也是离try最近的一个与异常V匹配的catch块）将被执行；这时就会有两种执行结果：<br />
  <br /> &#8211;&gt;如果catch块执行正常，那么finally块将会被执行，这时分为两种情况：<br />
  <br /> &#8212;-&gt;如果finally块执行顺利，那么整个try-catch-finally程序块正常完成。<br />
  <br /> &#8212;-&gt;如果finally块由于原因R突然中止，那么try-catch-finally程序块的结局是“由于原因R突然中止（completes abruptly）”<br />
  <br /> &#8211;&gt;如果catch块由于原因R突然中止，那么finally模块将被执行，分为两种情况：<br />
  <br /> &#8212;-&gt;如果finally块执行顺利，那么整个try-catch-finally程序块的结局是“由于原因R突然中止（completes abruptly）”。<br />
  <br /> &#8212;-&gt;如果finally块由于原因S突然中止，那么整个try-catch-finally程序块的结局是“由于原因S突然中止（completes abruptly）”，原因R将被抛弃。<br />
  <br /> （注意，这里就正好和我们的例子相符合，虽然我们在testEx2中使用throw e抛出了异常，但是由于testEx2中有finally块，而finally块的执行结果是complete abruptly的（别小看这个用得最多的return，它也是一种导致complete abruptly的原因之一啊——后文中有关于导致complete abruptly的原因分析），所以整个try-catch-finally程序块的结果是“complete abruptly”，所以在testEx1中调用testEx2时是捕捉不到testEx1中抛出的那个异常的，而只能将finally中的return结果获取到。<br />
  <br /> 如果在你的代码中期望通过捕捉被调用的下级函数的异常来给定返回值，那么一定要注意你所调用的下级函数中的finally语句，它有可能会使你throw出来的异常并不能真正被上级调用函数可见的。当然这种情况是可以避免的，以testEx2为例：如果你一定要使用finally而且又要将catch中throw的e在testEx1中被捕获到，那么你去掉testEx2中的finally中的return就可以了。这个事情已经在OMC2.0的MIB中出现过啦：服务器的异常不能完全被反馈到客户端。）<br />
  <br /> &#8211;&gt;如果异常V没有catch块与之匹配，那么finally模块将被执行，分为两种情况：<br />
  <br /> &#8212;-&gt;如果finally块执行顺利，那么整个try-catch-finally程序块的结局就是“由于抛出异常V而突然中止（completes abruptly）”。<br />
  <br /> &#8212;-&gt;如果finally块由于原因S突然中止，那么整个try-catch-finally程序块的结局是“由于原因S突然中止（completes abruptly）”，异常V将被抛弃。<br />
  <br /> 3．如果try由于其他原因R突然中止（completes abruptly），那么finally块被执行，分为两种情况：<br />
  <br /> &#8211;&gt;如果finally块执行顺利，那么整个try-catch-finally程序块的结局是“由于原因R突然中止（completes abruptly）”。<br />
  <br /> &#8211;&gt;如果finally块由于原因S突然中止，那么整个try-catch-finally程序块的结局是“由于原因S突然中止（completes abruptly）”，原因R将被抛弃。<br />
  <br /> 3.4 try-catch-finally程序块中的return<br />
  <br /> 从上面的try-catch-finally程序块的执行流程以及执行结果一节中可以看出无论try或catch中发生了什么情况，finally都是会被执行的，那么写在try或者catch中的return语句也就不会真正的从该函数中跳出了，它的作用在这种情况下就变成了将控制权（语句流程）转到finally块中；这种情况下一定要注意返回值的处理。<br />
  <br /> 例如，在try或者catch中return false了，而在finally中又return true，那么这种情况下不要期待你的try或者catch中的return false的返回值false被上级调用函数获取到，上级调用函数能够获取到的只是finally中的返回值，因为try或者catch中的return语句只是转移控制权的作用。<br />
  <br /> 3.5 如何抛出异常<br />
  <br /> 如果你知道你写的某个函数有可能抛出异常，而你又不想在这个函数中对异常进行处理，只是想把它抛出去让调用这个函数的上级调用函数进行处理，那么有两种方式可供选择：<br />
  <br /> 第一种方式：直接在函数头中throws SomeException，函数体中不需要try/catch。比如将最开始的例子中的testEx2改为下面的方式，那么testEx1就能捕捉到testEx2抛出的异常了。<br />
  </p>
<pre><code class="language-java">boolean testEx2() throws Exception{
        boolean ret = true;
        int b=12;
        int c;
        for (int i=2;i&gt;=-2;i--){
            c=b/i;
            System.out.println("i="+i);
        }
        return true;   
}</code></pre>
<p>第二种方式：使用try/catch，在catch中进行一定的处理之后（如果有必要的话）抛出某种异常。例如上面的testEx2改为下面的方式，testEx1也能捕获到它抛出的异常：<br />
  </p>
<pre><code class="language-java">boolean testEx2() throws Exception{
        boolean ret = true;
        try{
            int b=12;
            int c;
            for (int i=2;i&gt;=-2;i--){
                c=b/i;
                System.out.println("i="+i);
            }
            return true;
        }catch (Exception e){
            System.out.println("testEx2, catch exception");
            Throw e;
        }
    }</code></pre>
<p>第三种方法：使用try/catch/finally，在catch中进行一定的处理之后（如果有必要的话）抛出某种异常。例如上面的testEx2改为下面的方式，testEx1也能捕获到它抛出的异常：</p>
<pre><code class="language-java">boolean testEx2() throws Exception{
        boolean ret = true;
        try{
            int b=12;
            int c;
            for (int i=2;i&gt;=-2;i--){
                c=b/i;
                System.out.println("i="+i);
                throw new Exception("aaa");
            }
            return true;
        }catch (java.lang.ArithmeticException e){
            System.out.println("testEx2, catch exception");
            ret = false;
            throw new Exception("aaa");
        }finally{
            System.out.println("testEx2, finally; return value="+ret);
        }
    }</code></pre>
<p> 4 关于abrupt completion<br />
  <br /> 前面提到了complete abruptly（暂且理解为“突然中止”或者“异常结束”吧），它主要包含了两种大的情形：abrupt completion of expressions and statements，下面就分两种情况进行解释。<br />
  <br /> 4.1 Normal and Abrupt Completion of Evaluation<br />
  <br /> 每一个表达式（expression）都有一种使得其包含的计算得以一步步进行的正常模式，如果每一步计算都被执行且没有异常抛出，那么就称这个表达式“正常结束（complete normally）”；如果这个表达式的计算抛出了异常，就称为“异常结束（complete abruptly）”。异常结束通常有一个相关联的原因（associated reason），通常也就是抛出一个异常V。<br />
  <br /> 与表达式、操作符相关的运行期异常有：<br />
  <br /> &#8211;&gt;A class instance creation expression, array creation expression , or string concatenation operatior expression throws an OutOfMemoryError if there is insufficient memory available.<br />
  <br /> &#8211;&gt;An array creation expression throws a NegativeArraySizeException if the value of any dimension expression is less than zero.<br />
  <br /> &#8211;&gt;A field access throws a NullPointerException if the value of the object reference &nbsp;expression is null.<br />
  <br /> &#8211;&gt;A method invocation expression that invokes an instance method throws a NullPointerException if the target reference is null.<br />
  <br /> &#8211;&gt;An array access throws a NullPointerException if the value of the array reference &nbsp;expression is null.<br />
  <br /> &#8211;&gt;An array access throws an ArrayIndexOutOfBoundsException if the value of the array index expression is negative or greater than or equal to the length of the array.<br />
  <br /> &#8211;&gt;A cast throws a ClassCastException if a cast is found to be impermissible at run time.<br />
  <br /> &#8211;&gt;An integer division or integer remainder operator throws an ArithmeticException if the value of the right-hand operand expression is zero.<br />
  <br /> &#8211;&gt;An assignment to an array component of reference type throws an ArrayStoreException when the value to be assigned is not compatible with the component type of the array.<br />
  <br /> 4.2 Normal and Abrupt Completion of Statements<br />
  <br /> 正常情况我们就不多说了，在这里主要是列出了abrupt completion的几种情况：<br />
  <br /> &#8211;&gt;break, continue, and return 语句将导致控制权的转换，从而使得statements不能正常地、完整地执行。<br />
  <br /> &#8211;&gt;某些表达式的计算也可能从java虚拟机抛出异常，这些表达式在上一小节中已经总结过了；一个显式的的throw语句也将导致异常的抛出。抛出异常也是导致控制权的转换的原因（或者说是阻止statement正常结束的原因）。<br />
  <br /> 如果上述事件发生了，那么这些statement就有可能使得其正常情况下应该都执行的语句不能完全被执行到，那么这些statement也就是被称为是complete abruptly.<br />
  <br /> 导致abrupt completion的几种原因：<br />
  <br /> &#8211;&gt;A break with no label<br />
  <br /> &#8211;&gt;A break with a given label<br />
  <br /> &#8211;&gt;A continue with no label<br />
  <br /> &#8211;&gt;A continue with a given label<br />
  <br /> &#8211;&gt;A return with no value<br />
  <br /> &#8211;&gt;A return with a given value A<br />
  <br /> &#8211;&gt;throw with a given value, including exceptions thrown by the Java virtual machine</p>
<p> 5 关于我们的编程的一点建议<br />
  <br /> 弄清楚try-catch-finally的执行情况后我们才能正确使用它。<br />
  <br /> 如果我们使用的是try-catch-finally语句块，而我们又需要保证有异常时能够抛出异常，那么在finally语句中就不要使用return语句了（finally语句块的最重要的作用应该是释放申请的资源），因为finally中的return语句会导致我们的throw e被抛弃，在这个try-catch-finally的外面将只能看到finally中的返回值（除非在finally中抛出异常）。（我们需要记住：不仅throw语句是abrupt completion 的原因，return、break、continue等这些看起来很正常的语句也是导致abrupt completion的原因。）</p>
</p></div>
</div>
]]></content:encoded>
										</item>
	</channel>
</rss>
